<?xml version="1.0" encoding="utf-8"?>
<robot name="robot" xmlns:xacro="http://www.ros.org/wiki/xacro">

  <xacro:include filename="$(find food_serving_robot)/urdf/ydlidar.urdf"/>
  <xacro:include filename="$(find food_serving_robot)/urdf/right_arm.xacro"/>
  <xacro:include filename="$(find food_serving_robot)/urdf/left_arm.xacro"/>

  <link name="robot_footprint">
  </link>
  <joint name="robot_footprint_joint" type="fixed">
    <parent link="robot_footprint"/>
    <child link="base_link"/>
    <origin xyz="0 0 0" rpy="0 0 0" />
 </joint>

  <link name="base_link">
    <inertial>
      <origin xyz="0 0 0" rpy="0 0 0" />
      <mass value="100"/>
      <inertia ixx="1000" ixy="0.0" ixz="0.0" iyy="1000" iyz="0.0" izz="1000"/>
      <origin rpy="0 0 0" xyz="0 0 0"/>
    </inertial>
    <visual>
      <origin xyz="0 0 0" rpy="0 0 0" />
      <geometry>
        <mesh filename="package://food_serving_robot/meshes/base_link.STL" />
      </geometry>
      <material name="">
        <color rgba="1 1 1 1" />
      </material>
    </visual>
    <collision>
      <origin xyz="0 0 0" rpy="0 0 0" />
      <geometry>
        <mesh filename="package://food_serving_robot/meshes/base_link.STL" />
      </geometry>
    </collision>
  </link>

  <link
    name="fr_wheel">
    <inertial>
      <mass value="15"/>
      <inertia ixx="0.14" ixy="0.0" ixz="0.0" iyy="0.14" iyz="0.0" izz="0.12"/>
      <origin rpy="1.5707 0 0" xyz="0 0 0"/> 
    </inertial>
    <visual>
      <origin xyz="0 0 0" rpy="0 0 1.57"/>
      <geometry>
        <mesh filename="package://food_serving_robot/meshes/wheel1.stl" />
      </geometry>
      <material
        name="">
        <color rgba="0.792156862745098 0.819607843137255 0.933333333333333 1" />
      </material>
    </visual>
    <!-- <collision>
      <origin xyz="0 0 0" rpy="0 0 1.57"/>
      <geometry>
        <mesh
          filename="package://food_serving_robot/meshes/wheel1.stl" />
      </geometry>
    </collision> -->
    <collision>
      <geometry>
      <cylinder length="0.05" radius="0.05"/>
        </geometry>
      <origin rpy="1.5707 0 0" xyz="0 0 0"/> 
    </collision>
  </link>

  <joint name="fr_wheel_joint" type="continuous">
    <origin xyz="0.3475 -0.349 0" rpy="0 0 0" />
    <parent link="base_link" />
    <child link="fr_wheel" />
    <axis xyz="0 1 0" />
  </joint>

  <link
    name="fl_wheel">
    <inertial>
      <mass value="15"/>
      <inertia ixx="0.14" ixy="0.0" ixz="0.0" iyy="0.14" iyz="0.0" izz="0.12"/>
      <origin rpy="1.5707 0 0" xyz="0 0 0"/> 
    </inertial>
    <visual>
      <origin xyz="0 0 0" rpy="0 0 3.14" />
      <geometry>
        <mesh
          filename="package://food_serving_robot/meshes/wheel2.stl" />
      </geometry>
      <material name="">
        <color rgba="0.792156862745098 0.819607843137255 0.933333333333 1" />
      </material>
    </visual>
    <collision>
      <geometry>
        <cylinder length="0.05" radius="0.05"/>
      </geometry>
      <origin rpy="1.5707 0 0" xyz="0 0 0"/> 
    </collision>
  </link>

  <joint
    name="fl_wheel_joint"
    type="continuous">
    <origin xyz="0.347499999999999 0.349000000000002 0" rpy="0 0 0" />
    <parent link="base_link" />
    <child link="fl_wheel" />
    <axis xyz="0 1 0" />
  </joint>

  <link
    name="rr_wheel">
    <inertial>
      <mass value="15"/>
      <inertia ixx="0.14" ixy="0.0" ixz="0.0" iyy="0.14" iyz="0.0" izz="0.12"/>
      <origin rpy="1.5707 0 0" xyz="0 0 0"/> 
    </inertial>
    <visual>
      <origin xyz="0 0 0" rpy="0 0 0" />
      <geometry>
        <mesh filename="package://food_serving_robot/meshes/wheel2.stl" />
      </geometry>
      <material name="">
        <color rgba="0.792156862745098 0.819607843137255 0.933333333333 1" />
      </material>
    </visual>
    <collision>
      <geometry>
        <cylinder length="0.05" radius="0.05"/>
      </geometry>
      <origin rpy="1.5707 0 0" xyz="0 0 0"/> 
    </collision>
  </link>

  <joint name="rr_wheel_joint" type="continuous">
    <origin xyz="-0.347499999999996 -0.349000000000004 0" rpy="0 0 0" />
    <parent link="base_link" />
    <child link="rr_wheel" />
    <axis xyz="0 1 0" />
  </joint>

  <link
    name="rl_wheel">
    <inertial>
      <mass value="15"/>
      <inertia ixx="0.14" ixy="0.0" ixz="0.0" iyy="0.14" iyz="0.0" izz="0.12"/>
      <origin rpy="1.5707 0 0" xyz="0 0 0"/> 
    </inertial>
    <visual>
      <origin xyz="0 0 0" rpy="0 0 1.57" />
      <geometry>
        <mesh filename="package://food_serving_robot/meshes/wheel1.stl" />
      </geometry>
      <material name="">
        <color rgba="0.792156862745098 0.819607843137255 0.9333333333333 1" />
      </material>
    </visual>
    <collision>
      <geometry>
        <cylinder length="0.05" radius="0.05"/>
      </geometry>
      <origin rpy="1.5707 0 0" xyz="0 0 0"/> 
    </collision>
  </link>

  <joint name="rl_wheel_joint" type="continuous">
    <origin xyz="-0.347500000000002 0.35 0" rpy="0 0 -3.14159265358979" />
    <parent link="base_link" />
    <child link="rl_wheel" />
    <axis xyz="0 -1 0" />
  </joint>

  <!-- Omni-Steer-Plugin -->
  <!-- <gazebo>
    <plugin name="omni_steer_drive_controller" filename="libgazebo_ros_planar_move.so">
       <commandTopic>cmd_vel</commandTopic>
       <odometryTopic>odom</odometryTopic>
       <odometryFrame>odom</odometryFrame>
       <odometryRate>50.0</odometryRate>
       <robotBaseFrame>robot_footprint</robotBaseFrame>
    </plugin>
  </gazebo> -->

  <gazebo>
    <plugin name="skid_steer_drive_controller" filename="libgazebo_ros_skid_steer_drive.so">
      <updateRate>100.0</updateRate>
      <robotNamespace>/</robotNamespace>
      <leftFrontJoint>fl_wheel_joint</leftFrontJoint>
      <rightFrontJoint>fr_wheel_joint</rightFrontJoint>
      <leftRearJoint>rl_wheel_joint</leftRearJoint>
      <rightRearJoint>rr_wheel_joint</rightRearJoint>
      <wheelSeparation>0.8</wheelSeparation>
      <wheelDiameter>0.1</wheelDiameter>
      <robotBaseFrame>robot_footprint</robotBaseFrame>
      <torque>50</torque>
      <topicName>cmd_vel</topicName>
      <broadcastTF>true</broadcastTF>
    </plugin>
  </gazebo>

   <!-- Depth Camera Intel RealSense D435i -->
  <link name="realsense_link">
    <!-- <collision>
      <origin xyz="0 0 0" rpy="0 0 0"/>
      <geometry>
       <mesh filename="package://food_serving_robot/meshes/realsense_link.stl"/>
      </geometry>
    </collision> -->
    <visual>
      <origin xyz="0 0 0" rpy="0 0 0"/>
      <geometry>
       <mesh filename="package://food_serving_robot/meshes/realsense_link.stl"/>
      </geometry>
    </visual>
    <inertial>
      <mass value="1e-5" />
      <origin xyz="0 0 0" rpy="0 0 0"/>
      <inertia ixx="1e-6" ixy="0" ixz="0" iyy="1e-6" iyz="0" izz="1e-6" />
    </inertial>
  </link>
   
  <joint name="realsense_joint" type="fixed">
    <parent link="base_link"/>
    <child link="realsense_link"/>
    <axis xyz="0 0 0" />
    <origin xyz="0.32 0 0.2" rpy="0 0 0"/>
  </joint>
  <joint name="realsense_optical_joint" type="fixed">
    <origin xyz="0 0 0" rpy="-1.5707 0 -1.5707"/>
    <parent link="realsense_link"/>
    <child link="realsense_optical_link"/>
  </joint>
  <link name="realsense_optical_link"/>
  
  <gazebo reference="realsense_link">
   <sensor name="realsense" type="depth">
    <update_rate>20</update_rate>
    <camera>
      <horizontal_fov>1.047198</horizontal_fov>
      <image>
        <width>640</width>
        <height>480</height>
        <format>R8G8B8</format>
      </image>
      <clip>
        <near>0.05</near>
        <far>3</far>
      </clip>
    </camera>
    <plugin name="realsense_controller" filename="libgazebo_ros_openni_kinect.so">
      <baseline>0.2</baseline>
      <alwaysOn>false</alwaysOn>
      <updateRate>1.0</updateRate>
      <cameraName>realsense_ir</cameraName>
      <imageTopicName>/realsense/color/image_raw</imageTopicName>
      <cameraInfoTopicName>/realsense/color/camera_info</cameraInfoTopicName>
      <depthImageTopicName>/realsense/depth/image_raw</depthImageTopicName>
      <depthImageInfoTopicName>/realsense/depth/camera_info</depthImageInfoTopicName>
      <pointCloudTopicName>/realsense/depth/points</pointCloudTopicName>
      <frameName>realsense_optical_link</frameName>
      <pointCloudCutoff>0.5</pointCloudCutoff>
      <pointCloudCutoffMax>3.0</pointCloudCutoffMax>
      <distortionK1>0.00000001</distortionK1>
      <distortionK2>0.00000001</distortionK2>
      <distortionK3>0.00000001</distortionK3>
      <distortionT1>0.00000001</distortionT1>
      <distortionT2>0.00000001</distortionT2>
      <CxPrime>0</CxPrime>
      <Cx>0</Cx>
      <Cy>0</Cy>
      <focalLength>0</focalLength>
      <hackBaseline>0</hackBaseline>
    </plugin>
   </sensor>
  </gazebo>

  <!-- Lidar -->
  <joint name="lidar_base_link_joint" type="fixed">
    <parent link="base_link"/>
    <child link="base_laser"/>
    <origin rpy="0 0 0" xyz="0.25 0 0.22"/>
    <axis rpy="0 0 0" xyz="0 0 0"/>
  </joint>

  <!-- Arm Joints -->
  <joint name="right_arm_joint" type="revolute">
    <origin xyz="-0.197 -0.201 1.1255" rpy="1.5708 0 0" />
    <parent link="base_link" />
    <child link="r_shoulder_hinge" />
    <axis xyz="0 0 -1" />
    <limit lower="0" upper="0" effort="0" velocity="0" />
  </joint>

  <joint name="left_arm_joint" type="revolute">
    <origin xyz="-0.197 0.201 1.1255" rpy="-1.5708 -1.57 0" />
    <parent link="base_link" />
    <child link="l_shoulder_hinge" />
    <axis xyz="0 0 -1" />
    <limit lower="0" upper="0" effort="0" velocity="0" />
  </joint>

  <gazebo>
    <plugin filename="libgazebo_ros_control.so" name="control">
      <robotNamespace>/</robotNamespace>
      <legacyModeNS>true</legacyModeNS>
    </plugin>
  </gazebo>

  <gazebo reference="fl_wheel_joint">
    <material>Gazebo/Grey</material>
    <mu1>0.5</mu1>
    <mu2>0.5</mu2>
    <selfCollide>true</selfCollide>
    <minDepth>0.003</minDepth>
  </gazebo>
  <gazebo reference="fr_wheel_joint">
    <material>Gazebo/Grey</material>
    <mu1>0.5</mu1>
    <mu2>0.5</mu2>
    <selfCollide>true</selfCollide>
    <minDepth>0.003</minDepth>
  </gazebo>
  <gazebo reference="rl_wheel_joint">
    <material>Gazebo/Grey</material>
    <mu1>0.5</mu1>
    <mu2>0.5</mu2>
    <selfCollide>true</selfCollide>
    <minDepth>0.003</minDepth>
  </gazebo>
  <gazebo reference="rr_wheel_joint">
    <material>Gazebo/Grey</material>
    <mu1>0.5</mu1>
    <mu2>0.5</mu2>
    <selfCollide>true</selfCollide>
    <minDepth>0.003</minDepth>
  </gazebo>

</robot>